Workbook
Name Employee_2: Hookup!$A$1:$P$6

Sheet City_and_State
D3: City | E3: State
D4: Mumbai | E4: Maharashtra
D5: Udaipur | E5: Rajasthan
D6: Lucknow | E6: UP
D7: Surat | E7: Gujrat
D8: Banaras | E8: UP
D9: Indore | E9: MP
D10: Pune | E10: Maharashtra
D11: Bhopal | E11: MP
D12: Jyotpur | E12: Rajasthan | H12: City | I12: Mumbai | J12: Udaipur | K12: Lucknow | L12: Surat | M12: Banaras | N12: Indore | O12: Pune | P12: Bhopal | Q12: Jyotpur | R12: Ahmdabaad | S12: Gorakhpur
D13: Ahmdabaad | E13: Gujrat | H13: State | I13: Maharashtra | J13: Rajasthan | K13: UP | L13: Gujrat | M13: UP | N13: MP | O13: Maharashtra | P13: MP | Q13: Rajasthan | R13: Gujrat | S13: UP
D14: Gorakhpur | E14: UP

Sheet VlookUp
A2: Name | B2: Age | C2: Salary | D2: TDS 3% | E2: Pass Out Year | F2: City | G2: State
A3: Ramesh | B3: 21 | C3: 25800 | D3: =C3*3% -> 774 | E3: 2016 | F3: Mumbai | G3: =IFERROR(VLOOKUP(F3,City_and_State!$D$3:$E$14,2,FALSE),"Not found") -> Maharashtra | J3: Select the entire range or dataset and Name it as a "Employee" from Name Box.
A4: Mahesh | B4: 43 | C4: 73000 | D4: =C4*3% -> 2190 | E4: 2014 | F4: Udaipur | G4: =IFERROR(VLOOKUP(F4,City_and_State!$D$3:$E$14,2,FALSE),"Not found") -> Rajasthan | J4: Remove the blank columns at once.
A5: Suresh | B5: 32 | C5: 54999 | D5: =C5*3% -> 1649.97 | E5: 2016 | F5: Lucknow | G5: =IFERROR(VLOOKUP(F5,City_and_State!$D$3:$E$14,2,FALSE),"Not found") -> UP | J5: Make the headers as bold and also make the background light blue.
A6: Jayesh | B6: 24 | C6: 45969 | D6: =C6*3% -> 1379.07 | E6: 2017 | F6: Surat | G6: =IFERROR(VLOOKUP(F6,City_and_State!$D$3:$E$14,2,FALSE),"Not found") -> Gujrat | J6: Give a border to the dataset ( or range).
A7: Jitesh | B7: 43 | C7: 65999 | D7: =C7*3% -> 1979.97 | E7: 2014 | F7: Banaras | G7: =IFERROR(VLOOKUP(F7,City_and_State!$D$3:$E$14,2,FALSE),"Not found") -> UP | J7: Change the font size of headers at once to 16.
A8: Gitesh | B8: 34 | C8: 85000 | D8: =C8*3% -> 2550 | E8: 2016 | F8: Indore | G8: =IFERROR(VLOOKUP(F8,City_and_State!$D$3:$E$14,2,FALSE),"Not found") -> MP | J8: Change the Data to there respected data-type of each column. (e.g. Name is should be "Text")
A9: kamlesh | B9: 32 | C9: 55869 | D9: =C9*3% -> 1676.07 | E9: 2016 | F9: Mumbai | K9: Column | L9: Data Type
A10: Hitesh | B10: 43 | C10: 58399 | D10: =C10*3% -> 1751.97 | E10: 2014 | F10: Pune | G10: =IFERROR(VLOOKUP(F10,City_and_State!$D$3:$E$14,2,FALSE),"Not found") -> Maharashtra | K10: Name | L10: Text
A11: Jay | B11: 23 | C11: 45858 | D11: =C11*3% -> 1375.74 | E11: 2019 | F11: Bhopal | K11: Age | L11: Number | M11: (* with no decimal values)
A12: ajay | B12: 25 | C12: 46899 | D12: =C12*3% -> 1406.97 | E12: 2019 | F12: Indore | G12: =IFERROR(VLOOKUP(F12,City_and_State!$D$3:$E$14,2,FALSE),"Not found") -> MP | K12: Salary | L12: Accounts
A13: Rajesh | B13: 28 | C13: 23500 | D13: =C13*3% -> 705 | E13: 2016 | F13: Jyotpur | G13: =IFERROR(VLOOKUP(F13,City_and_State!$D$3:$E$14,2,FALSE),"Not found") -> Rajasthan | K13: City | L13: Text
A14: Sujay | B14: 32 | C14: 38000 | D14: =C14*3% -> 1140 | E14: 2014 | F14: Ahmdabaad | G14: =IFERROR(VLOOKUP(F14,City_and_State!$D$3:$E$14,2,FALSE),"Not found") -> Gujrat | K14: State | L14: Text
A15: Sanjay | B15: 43 | C15: 28500 | D15: =C15*3% -> 855 | E15: 2019 | F15: Surat | G15: =IFERROR(VLOOKUP(F15,City_and_State!$D$3:$E$14,2,FALSE),"Not found") -> Gujrat
A16: Dhananjay | B16: 20 | C16: 48800 | D16: =C16*3% -> 1464 | E16: 2019 | F16: Gorakhpur | G16: =IFERROR(VLOOKUP(F16,City_and_State!$D$3:$E$14,2,FALSE),"Not found") -> UP | J16: Highlight the entire rows whose age is less then 30 in red color.
A17: Nirjay | B17: 37 | C17: 57300 | D17: =C17*3% -> 1719 | E17: 2014 | F17: Pune | G17: =IFERROR(VLOOKUP(F17,City_and_State!$D$3:$E$14,2,FALSE),"Not found") -> Maharashtra | J17: Find the TDS 3% of salary for each person.
A18: Rohan | B18: 19 | C18: 25000 | D18: =C18*3% -> 750 | E18: 2015 | F18: Mizoram | G18: =IFERROR(VLOOKUP(F18,City_and_State!$D$3:$E$14,2,FALSE),"Not found") -> Not found
J20: Use the City_and_State sheet and fill the Sate column of current sheet using lookup.
J21: Handle the N/A or any other error if occure.
J23: Find the following data of "Gitesh" using Vlookup.
J24: Name | K24: Gitesh
J26: Age | K26: =VLOOKUP(K24,A3:F18,2,FALSE) -> 34
J27: Salary | K27: =VLOOKUP("Gitesh",A3:G18,3,FALSE) -> 85000
J28: City | K28: =VLOOKUP("Gitesh",A3:G18,6,FALSE) -> Indore
J29: Pass out Yr | K29: =VLOOKUP("Gitesh",A3:G18,5,FALSE) -> 2016

Sheet Hookup
A1: Name | B1: Ramesh | C1: Mahesh | D1: Suresh | E1: Jayesh | F1: Jitesh | G1: Gitesh | H1: kamlesh | I1: Hitesh | J1: Jay | K1: ajay | L1: Rajesh | M1: Sujay | N1: Sanjay | O1: Dhananjay | P1: Nirjay
A2: Age | B2: 21 | C2: 43 | D2: 32 | E2: 24 | F2: 43 | G2: 34 | H2: 32 | I2: 43 | J2: 23 | K2: 25 | L2: 28 | M2: 32 | N2: 43 | O2: 20 | P2: 37
A3: Salary | B3: 25800 | C3: 73000 | D3: 54999 | E3: 45969 | F3: 65999 | G3: 85000 | H3: 55869 | I3: 58399 | J3: 45858 | K3: 46899 | L3: 23500 | M3: 38000 | N3: 28500 | O3: 48800 | P3: 57300
A4: Pass Out Year | B4: 2016 | C4: 2014 | D4: 2016 | E4: 2017 | F4: 2014 | G4: 2016 | H4: 2016 | I4: 2014 | J4: 2019 | K4: 2019 | L4: 2016 | M4: 2014 | N4: 2019 | O4: 2019 | P4: 2014
A5: City | B5: Mumbai | C5: Udaipur | D5: Lucknow | E5: Surat | F5: Banaras | G5: Indore | H5: Mumbai | I5: Pune | J5: Bhopal | K5: Indore | L5: Jyotpur | M5: Ahmdabaad | N5: Surat | O5: Gorakhpur | P5: Pune
A6: State | B6: =IFERROR(HLOOKUP(B5,City_and_State!$H$12:$S$13,2,FALSE),"Not Fund") -> Maharashtra | C6: =IFERROR(HLOOKUP(C5,City_and_State!$H$12:$S$13,2,FALSE),"Not Fund") -> Rajasthan | D6: =IFERROR(HLOOKUP(D5,City_and_State!$H$12:$S$13,2,FALSE),"Not Fund") -> UP | E6: =IFERROR(HLOOKUP(E5,City_and_State!$H$12:$S$13,2,FALSE),"Not Fund") -> Gujrat | F6: =IFERROR(HLOOKUP(F5,City_and_State!$H$12:$S$13,2,FALSE),"Not Fund") -> UP | G6: =IFERROR(HLOOKUP(G5,City_and_State!$H$12:$S$13,2,FALSE),"Not Fund") -> MP | H6: =IFERROR(HLOOKUP(H5,City_and_State!$H$12:$S$13,2,FALSE),"Not Fund") -> Maharashtra | I6: =IFERROR(HLOOKUP(I5,City_and_State!$H$12:$S$13,2,FALSE),"Not Fund") -> Maharashtra | ... P6: =IFERROR(HLOOKUP(P5,City_and_State!$H$12:$S$13,2,FALSE),"Not Fund") -> Maharashtra
B8: Go to "Data Set 1" and copy the entire data and paste by using Transpore property so the data should look like above.
B9: Remove the blank rows at once if any..
B10: Fill the State row use the "City_and_state" sheet while using loop.
B11: Select the entire range or dataset and Name it as a "Employee_2" from Name Box.
B13: Bold the headers and also make the background light blue.
B14: Give a border to the dataset or range.
B15: Change the font size of headers at once.
B16: Change the Data to there respected data-type of each column. (e.g. Name is should be "Text")
C17: Column | D17: Data Type
C18: Name | D18: Text
C19: Age | D19: Number | E19: (* with no decimal values)
C20: Salary | D20: Accounts
C21: City | D21: Text
C22: State | D22: Text
B24: Highlight the entire rows whose age is less then 30.
B26: Find the following data of "Gitesh" using Hlookup.
B27: Name | C27: Gitesh
B29: Age | C29: =HLOOKUP(C27,B1:P5,2,0) -> 34
B30: Salary | C30: =HLOOKUP(C27,Employee_2,3,FALSE) -> 85000
B31: City | C31: =HLOOKUP(C27,Employee_2,5,FALSE) -> Indore
B32: Pass out Yr | C32: =HLOOKUP(Hookup!C27,Employee_2,4,FALSE) -> 2016

Sheet cansole1
A1: Sales of Finacial Year 2019-20
A2: Product | B2: Q1 | C2: Q2 | D2: Q3 | E2: Q4
A3: Laptop | B3: 200000 | C3: 200005 | D3: 400000 | E3: 420000
A4: Mobile | B4: 300000 | C4: 350000 | D4: 200000 | E4: 500000
A5: Washing Machine | B5: 120000 | C5: 120001 | D5: 150000 | E5: 160003
A6: Smart Watches | B6: 40000 | C6: 50001 | D6: 40006 | E6: 60007
A7: Tabs | B7: 90000 | C7: 100001 | D7: 80002 | E7: 85003
A8: Smart Pens | B8: 23000 | C8: 25001 | D8: 25002 | E8: 33003

Sheet cansole2
A1: Sales of Finacial Year 2018-19
A2: Product | B2: Q1 | C2: Q2 | D2: Q3 | E2: Q4
A3: Laptop | B3: 100000 | C3: 100005 | D3: 200000 | E3: 320000
A4: Mobile | B4: 200000 | C4: 320000 | D4: 300000 | E4: 700000
A5: Washing Machine | B5: 100000 | C5: 150001 | D5: 150000 | E5: 180003
A6: Smart Watches | B6: 20000 | C6: 50001 | D6: 30006 | E6: 70007
A7: Tabs | B7: 100000 | C7: 100001 | D7: 80002 | E7: 95003
A8: Smart Pens | B8: 20000 | C8: 35001 | D8: 35002 | E8: 43003

Sheet Sales_data_set
B2: Sales | C2: Commission % | D2: Rating | H2: Sales | J2: Commission % | K2: Rating
B3: 100000 | C3: =VLOOKUP(B3,$H$4:$K$8,3,TRUE) -> 0.02 | D3: =VLOOKUP(B3,$H$4:$K$8,4,TRUE) -> 1 | H3: Min Range | I3: Max Range
B4: 120000 | C4: =VLOOKUP(B4,$H$4:$K$8,3,TRUE) -> 0.04 | D4: =VLOOKUP(B4,$H$4:$K$8,4,TRUE) -> 2 | H4: 10000 | I4: 100000 | J4: 0.02 | K4: 1
B5: 50000 | C5: =VLOOKUP(B5,$H$4:$K$8,3,TRUE) -> 0.02 | D5: =VLOOKUP(B5,$H$4:$K$8,4,TRUE) -> 1 | H5: 100001 | I5: 200000 | J5: 0.04 | K5: 2
B6: 90000 | C6: =VLOOKUP(B6,$H$4:$K$8,3,TRUE) -> 0.02 | D6: =VLOOKUP(B6,$H$4:$K$8,4,TRUE) -> 1 | H6: 200001 | I6: 300000 | J6: 0.06 | K6: 3
B7: 800000 | C7: =VLOOKUP(B7,$H$4:$K$8,3,TRUE) -> 0.1 | D7: =VLOOKUP(B7,$H$4:$K$8,4,TRUE) -> 5 | H7: 300001 | I7: 400000 | J7: 0.08 | K7: 4
B8: 200000 | C8: =VLOOKUP(B8,$H$4:$K$8,3,TRUE) -> 0.04 | D8: =VLOOKUP(B8,$H$4:$K$8,4,TRUE) -> 2 | H8: 400001 | I8: Above | J8: 0.1 | K8: 5
B9: 80000 | C9: =VLOOKUP(B9,$H$4:$K$8,3,TRUE) -> 0.02 | D9: =VLOOKUP(B9,$H$4:$K$8,4,TRUE) -> 1
B10: 90000 | C10: =VLOOKUP(B10,$H$4:$K$8,3,TRUE) -> 0.02 | D10: =VLOOKUP(B10,$H$4:$K$8,4,TRUE) -> 1
B11: 400000 | C11: =VLOOKUP(B11,$H$4:$K$8,3,TRUE) -> 0.08 | D11: =VLOOKUP(B11,$H$4:$K$8,4,TRUE) -> 4 | H11: Use lookups.
B12: 300000 | C12: =VLOOKUP(B12,$H$4:$K$8,3,TRUE) -> 0.06 | D12: =VLOOKUP(B12,$H$4:$K$8,4,TRUE) -> 3 | H12: Base on sales range commission % and rating are give use above table and fill the data.
B13: 450000 | C13: =VLOOKUP(B13,$H$4:$K$8,3,TRUE) -> 0.1 | D13: =VLOOKUP(B13,$H$4:$K$8,4,TRUE) -> 5
B14: 300000 | C14: =VLOOKUP(B14,$H$4:$K$8,3,TRUE) -> 0.06 | D14: =VLOOKUP(B14,$H$4:$K$8,4,TRUE) -> 3
B15: 400000 | C15: =VLOOKUP(B15,$H$4:$K$8,3,TRUE) -> 0.08 | D15: =VLOOKUP(B15,$H$4:$K$8,4,TRUE) -> 4
B16: 500000 | C16: =VLOOKUP(B16,$H$4:$K$8,3,TRUE) -> 0.1 | D16: =VLOOKUP(B16,$H$4:$K$8,4,TRUE) -> 5
B17: 900000 | C17: =VLOOKUP(B17,$H$4:$K$8,3,TRUE) -> 0.1 | D17: =VLOOKUP(B17,$H$4:$K$8,4,TRUE) -> 5
B18: 400000 | C18: =VLOOKUP(B18,$H$4:$K$8,3,TRUE) -> 0.08 | D18: =VLOOKUP(B18,$H$4:$K$8,4,TRUE) -> 4
B21: Sales | C21: Commission % | D21: Rating | H21: Sales | I21: Min Range | J21: 10000 | K21: 100001 | L21: 200001 | M21: 300001 | N21: 400001
B22: 100000 | C22: =HLOOKUP(B22,$J$21:$N$24,3,TRUE) -> 0.02 | D22: =HLOOKUP(B22,$J$21:$N$24,4,TRUE) -> 1 | I22: Max Range | J22: 100000 | K22: 200000 | L22: 300000 | M22: 400000 | N22: Above
B23: 120000 | C23: =HLOOKUP(B23,$J$21:$N$24,3,TRUE) -> 0.04 | D23: =HLOOKUP(B23,$J$21:$N$24,4,TRUE) -> 2 | H23: Commission % | J23: 0.02 | K23: 0.04 | L23: 0.06 | M23: 0.08 | N23: 0.1
B24: 50000 | C24: =HLOOKUP(B24,$J$21:$N$24,3,TRUE) -> 0.02 | D24: =HLOOKUP(B24,$J$21:$N$24,4,TRUE) -> 1 | H24: Rating | J24: 1 | K24: 2 | L24: 3 | M24: 4 | N24: 5
B25: 90000 | C25: =HLOOKUP(B25,$J$21:$N$24,3,TRUE) -> 0.02 | D25: =HLOOKUP(B25,$J$21:$N$24,4,TRUE) -> 1
B26: 800000 | C26: =HLOOKUP(B26,$J$21:$N$24,3,TRUE) -> 0.1 | D26: =HLOOKUP(B26,$J$21:$N$24,4,TRUE) -> 5
B27: 200000 | C27: =HLOOKUP(B27,$J$21:$N$24,3,TRUE) -> 0.04 | D27: =HLOOKUP(B27,$J$21:$N$24,4,TRUE) -> 2 | H27: Use Hlookup and fill the data.
B28: 80000 | C28: =HLOOKUP(B28,$J$21:$N$24,3,TRUE) -> 0.02 | D28: =HLOOKUP(B28,$J$21:$N$24,4,TRUE) -> 1
B29: 90000 | C29: =HLOOKUP(B29,$J$21:$N$24,3,TRUE) -> 0.02 | D29: =HLOOKUP(B29,$J$21:$N$24,4,TRUE) -> 1
B30: 400000 | C30: =HLOOKUP(B30,$J$21:$N$24,3,TRUE) -> 0.08 | D30: =HLOOKUP(B30,$J$21:$N$24,4,TRUE) -> 4
B31: 300000 | C31: =HLOOKUP(B31,$J$21:$N$24,3,TRUE) -> 0.06 | D31: =HLOOKUP(B31,$J$21:$N$24,4,TRUE) -> 3
B32: 450000 | C32: =HLOOKUP(B32,$J$21:$N$24,3,TRUE) -> 0.1 | D32: =HLOOKUP(B32,$J$21:$N$24,4,TRUE) -> 5
B33: 300000 | C33: =HLOOKUP(B33,$J$21:$N$24,3,TRUE) -> 0.06 | D33: =HLOOKUP(B33,$J$21:$N$24,4,TRUE) -> 3
B34: 400000 | C34: =HLOOKUP(B34,$J$21:$N$24,3,TRUE) -> 0.08 | D34: =HLOOKUP(B34,$J$21:$N$24,4,TRUE) -> 4
B35: 500000 | C35: =HLOOKUP(B35,$J$21:$N$24,3,TRUE) -> 0.1 | D35: =HLOOKUP(B35,$J$21:$N$24,4,TRUE) -> 5
B36: 900000 | C36: =HLOOKUP(B36,$J$21:$N$24,3,TRUE) -> 0.1 | D36: =HLOOKUP(B36,$J$21:$N$24,4,TRUE) -> 5
B37: 400000 | C37: =HLOOKUP(B37,$J$21:$N$24,3,TRUE) -> 0.08 | D37: =HLOOKUP(B37,$J$21:$N$24,4,TRUE) -> 4

Sheet cansole3
A1: Sales of Finacial Year 2017-16
A2: Product | B2: Q1 | C2: Q2 | D2: Q3 | E2: Q4
A3: Laptop | B3: 50000 | C3: 100005 | D3: 200000 | E3: 450000
A4: Mobile | B4: 200000 | C4: 350000 | D4: 300000 | E4: 400000
A5: Washing Machine | B5: 150000 | C5: 160001 | D5: 180000 | E5: 170003
A6: Smart Watches | B6: 20000 | C6: 70001 | D6: 40006 | E6: 60007
A7: Tabs | B7: 70000 | C7: 100001 | D7: 180002 | E7: 85003
A8: Smart Pens | B8: 20000 | C8: 24001 | D8: 35002 | E8: 33003

Sheet Cansolidate
C2: Use the consolidate . | T2: Use the consolidate .
C3: Find the total sales of each product from year 17-16 to 19-18 | M3: (i.e. from Cansole 1 to 3) | T3: Find the total sales of each product from year 17-16 to 19-18 | AA3: Total
C4: Find the max sales of each product from year 17-16 to 19-19 | T4: Find the max sales of each product from year 17-16 to 19-19 | AB4: Q1 | AC4: Q2 | AD4: Q3 | AE4: Q4
C5: Find the min sales of each product from year 17-16 to 19-20 | T5: Find the min sales of each product from year 17-16 to 19-20 | AA5: Laptop | AB5: 150000 | AC5: 200010 | AD5: 400000 | AE5: 770000
C6: Find the average sales of each product from year 17-16 to 19-21 | T6: Find the average sales of each product from year 17-16 to 19-21 | AA6: Mobile | AB6: 400000 | AC6: 670000 | AD6: 600000 | AE6: 1100000
AA7: Washing Machine | AB7: 250000 | AC7: 310002 | AD7: 330000 | AE7: 350006
C8: Note: | H8: In output header row and Product column should be there. | U8: In output header row and Product column should be there. | AA8: Smart Watches | AB8: 40000 | AC8: 120002 | AD8: 70012 | AE8: 130014
H9: If there will be any change in main data change should be reflect in consolidated data. | AA9: Tabs | AB9: 170000 | AC9: 200002 | AD9: 260004 | AE9: 180006
AA10: Smart Pens | AB10: 40000 | AC10: 59002 | AD10: 70004 | AE10: 76006
C11: Hint* : | H11: Will have 4 different table for each Question.
T12: MAX | AA12: Max
U13: Q1 | V13: Q2 | W13: Q3 | X13: Q4
T14: Laptop | U14: 200000 | V14: 200005 | W14: 400000 | X14: 450000
T15: Mobile | U15: 300000 | V15: 350000 | W15: 300000 | X15: 700000
T16: Washing Machine | U16: 150000 | V16: 160001 | W16: 180000 | X16: 180003 | AB16: Q1 | AC16: Q2 | AD16: Q3 | AE16: Q4
T17: Smart Watches | U17: 40000 | V17: 70001 | W17: 40006 | X17: 70007 | AA17: Laptop | AB17: 100000 | AC17: 100005 | AD17: 200000 | AE17: 450000
T18: Tabs | U18: 100000 | V18: 100001 | W18: 180002 | X18: 95003 | AA18: Mobile | AB18: 200000 | AC18: 350000 | AD18: 300000 | AE18: 700000
C19: Total | T19: Smart Pens | U19: 23000 | V19: 35001 | W19: 35002 | X19: 43003 | AA19: Washing Machine | AB19: 150000 | AC19: 160001 | AD19: 180000 | AE19: 180003
AA20: Smart Watches | AB20: 20000 | AC20: 70001 | AD20: 40006 | AE20: 70007
AA21: Tabs | AB21: 100000 | AC21: 100001 | AD21: 180002 | AE21: 95003
H22: Q1 | I22: Q2 | J22: Q3 | K22: Q4 | AA22: Smart Pens | AB22: 20000 | AC22: 35001 | AD22: 35002 | AE22: 43003
G25: 3 | H25: =cansole1!$B$3 -> 200000 | I25: =cansole1!$C$3 -> 200005 | J25: =cansole1!$D$3 -> 400000 | K25: =cansole1!$E$3 -> 420000
G28: 3 | H28: =cansole2!$B$3 -> 100000 | I28: =cansole2!$C$3 -> 100005 | J28: =cansole2!$D$3 -> 200000 | K28: =cansole2!$E$3 -> 320000
G31: 3 | H31: =cansole3!$B$3 -> 50000 | I31: =cansole3!$C$3 -> 100005 | J31: =cansole3!$D$3 -> 200000 | K31: =cansole3!$E$3 -> 450000
C32: Laptop | H32: =SUM(H25:H31) -> 350000 | I32: =SUM(I25:I31) -> 400015 | J32: =SUM(J25:J31) -> 800000 | K32: =SUM(K25:K31) -> 1190000
G33: 3 | H33: =cansole1!$B$4 -> 300000 | I33: =cansole1!$C$4 -> 350000 | J33: =cansole1!$D$4 -> 200000 | K33: =cansole1!$E$4 -> 500000
G34: 3 | H34: =cansole2!$B$4 -> 200000 | I34: =cansole2!$C$4 -> 320000 | J34: =cansole2!$D$4 -> 300000 | K34: =cansole2!$E$4 -> 700000
G35: 3 | H35: =cansole3!$B$4 -> 200000 | I35: =cansole3!$C$4 -> 350000 | J35: =cansole3!$D$4 -> 300000 | K35: =cansole3!$E$4 -> 400000
C36: Mobile | H36: =SUM(H33:H35) -> 700000 | I36: =SUM(I33:I35) -> 1020000 | J36: =SUM(J33:J35) -> 800000 | K36: =SUM(K33:K35) -> 1600000
G37: 3 | H37: =cansole1!$B$5 -> 120000 | I37: =cansole1!$C$5 -> 120001 | J37: =cansole1!$D$5 -> 150000 | K37: =cansole1!$E$5 -> 160003
G38: 3 | H38: =cansole2!$B$5 -> 100000 | I38: =cansole2!$C$5 -> 150001 | J38: =cansole2!$D$5 -> 150000 | K38: =cansole2!$E$5 -> 180003
G39: 3 | H39: =cansole3!$B$5 -> 150000 | I39: =cansole3!$C$5 -> 160001 | J39: =cansole3!$D$5 -> 180000 | K39: =cansole3!$E$5 -> 170003
C40: Washing Machine | H40: =SUM(H37:H39) -> 370000 | I40: =SUM(I37:I39) -> 430003 | J40: =SUM(J37:J39) -> 480000 | K40: =SUM(K37:K39) -> 510009 | AA40: MIN
G41: 3 | H41: =cansole1!$B$6 -> 40000 | I41: =cansole1!$C$6 -> 50001 | J41: =cansole1!$D$6 -> 40006 | K41: =cansole1!$E$6 -> 60007
G42: 3 | H42: =cansole2!$B$6 -> 20000 | I42: =cansole2!$C$6 -> 50001 | J42: =cansole2!$D$6 -> 30006 | K42: =cansole2!$E$6 -> 70007
G43: 3 | H43: =cansole3!$B$6 -> 20000 | I43: =cansole3!$C$6 -> 70001 | J43: =cansole3!$D$6 -> 40006 | K43: =cansole3!$E$6 -> 60007
C44: Smart Watches | H44: =SUM(H41:H43) -> 80000 | I44: =SUM(I41:I43) -> 170003 | J44: =SUM(J41:J43) -> 110018 | K44: =SUM(K41:K43) -> 190021 | AB44: Q1 | AC44: Q2 | AD44: Q3 | AE44: Q4
P45: Assignment_3 | Q45: =cansole1!$B$3 -> 200000 | R45: =cansole1!$C$3 -> 200005 | S45: =cansole1!$D$3 -> 400000 | T45: =cansole1!$E$3 -> 420000
P46: Assignment_3 | Q46: =cansole2!$B$3 -> 100000 | R46: =cansole2!$C$3 -> 100005 | S46: =cansole2!$D$3 -> 200000 | T46: =cansole2!$E$3 -> 320000
G47: 3 | H47: =cansole1!$B$7 -> 90000 | I47: =cansole1!$C$7 -> 100001 | J47: =cansole1!$D$7 -> 80002 | K47: =cansole1!$E$7 -> 85003 | O47: Laptop | Q47: =SUM(Q45:Q46) -> 300000 | R47: =SUM(R45:R46) -> 300010 | S47: =SUM(S45:S46) -> 600000 | T47: =SUM(T45:T46) -> 740000 | AA47: Laptop | AB47: 200000 | AC47: 200005 | AD47: 400000 | AE47: 450000
...

Sheet Match
A1: Sales of Finacial Year 2018-19
A2: Product | B2: Q1 | C2: Q2 | D2: Q3 | E2: Q4 | H2: What is the Column Number of Q1. | M2: =MATCH(B2,A2:E2,0) -> 2
A3: Laptop | B3: 100000 | C3: 100005 | D3: 200000 | E3: 320000 | H3: What is the column number of Smart Watches. | M3: =MATCH(A6,A6:E6,0) -> 1
A4: Mobile | B4: 200000 | C4: 320000 | D4: 300000 | E4: 700000 | H4: What is the column number of Q4. | M4: =MATCH(E2,A2:E2,0) -> 5
A5: Washing Machine | B5: 100000 | C5: 150001 | D5: 150000 | E5: 180003 | H5: What is the row number of 43,003. | M5: =MATCH(E8,E2:E8,0) -> 7
A6: Smart Watches | B6: 20000 | C6: 50001 | D6: 30006 | E6: 70007 | H6: What is the row number of Q4. | M6: =MATCH(E2,E2:E8,0) -> 1
A7: Tabs | B7: 100000 | C7: 100001 | D7: 80002 | E7: 95003
A8: Smart Pens | B8: 20000 | C8: 35001 | D8: 35002 | E8: 43003
